OrderBookSim/OrderBookSim/Outputs/Log1362054036.txt
0--INFO	Added rule
0--INFO	Added rule
0--INFO	Added rule
0--INFO	Added rule
860--INFO	Enqueued order: Price: 0.00, Volume: 100, Type: SELL, Market Order: 1, Participant: 9, Stock:[ID: 0, Symbol: GOOG], Time: 860, OrderNumber: 0
993--INFO	Enqueued order: Price: 0.00, Volume: 100, Type: SELL, Market Order: 1, Participant: 8, Stock:[ID: 0, Symbol: GOOG], Time: 993, OrderNumber: 1
1257--INFO	Enqueued order: Price: 0.00, Volume: 100, Type: SELL, Market Order: 1, Participant: 11, Stock:[ID: 0, Symbol: GOOG], Time: 1257, OrderNumber: 2
1330--INFO	Enqueued order: Price: 0.00, Volume: 100, Type: SELL, Market Order: 1, Participant: 10, Stock:[ID: 0, Symbol: GOOG], Time: 1330, OrderNumber: 3
1514--INFO	Enqueued order: Price: 2147483647.00, Volume: 324, Type: BUY, Market Order: 1, Participant: 3, Stock:[ID: 0, Symbol: GOOG], Time: 1514, OrderNumber: 4
1515--INFO	Last Price Set:100.00
1515--INFO	Notified Traders of trade1515---Trade ID: 0, Price: 100.00, Volume: 100 between ID:[3] and ID:[9]
1515--INFO	Last Price Set:100.00
1515--INFO	Notified Traders of trade1515---Trade ID: 1, Price: 100.00, Volume: 100 between ID:[3] and ID:[8]
1515--INFO	Last Price Set:100.00
1515--INFO	Notified Traders of trade1515---Trade ID: 2, Price: 100.00, Volume: 100 between ID:[3] and ID:[11]
1515--INFO	Last Price Set:100.00
1515--INFO	Notified Traders of trade1515---Trade ID: 3, Price: 100.00, Volume: 24 between ID:[3] and ID:[10]
1720--INFO	Enqueued order: Price: 2147483647.00, Volume: 137500, Type: BUY, Market Order: 1, Participant: 9, Stock:[ID: 0, Symbol: GOOG], Time: 1720, OrderNumber: 5
1721--INFO	Last Price Set:100.00
1721--INFO	Notified Traders of trade1721---Trade ID: 4, Price: 100.00, Volume: 100 between ID:[9] and ID:[10]
1986--INFO	Enqueued order: Price: 2147483647.00, Volume: 137500, Type: BUY, Market Order: 1, Participant: 8, Stock:[ID: 0, Symbol: GOOG], Time: 1986, OrderNumber: 6
2514--INFO	Enqueued order: Price: 2147483647.00, Volume: 137500, Type: BUY, Market Order: 1, Participant: 11, Stock:[ID: 0, Symbol: GOOG], Time: 2514, OrderNumber: 7
2580--INFO	Enqueued order: Price: 0.00, Volume: 100, Type: SELL, Market Order: 1, Participant: 9, Stock:[ID: 0, Symbol: GOOG], Time: 2580, OrderNumber: 8
2581--INFO	Last Price Set:100.00
2581--INFO	Notified Traders of trade2581---Trade ID: 5, Price: 100.00, Volume: 100 between ID:[8] and ID:[9]
2660--INFO	Enqueued order: Price: 2147483647.00, Volume: 167500, Type: BUY, Market Order: 1, Participant: 10, Stock:[ID: 0, Symbol: GOOG], Time: 2660, OrderNumber: 9
2679--INFO	Enqueued order: Price: 0.00, Volume: 764, Type: SELL, Market Order: 1, Participant: 1, Stock:[ID: 0, Symbol: GOOG], Time: 2679, OrderNumber: 10
2680--INFO	Last Price Set:100.00
2680--INFO	Notified Traders of trade2680---Trade ID: 6, Price: 100.00, Volume: 764 between ID:[9] and ID:[1]
2882--INFO	Enqueued order: Price: 0.00, Volume: 564, Type: SELL, Market Order: 1, Participant: 2, Stock:[ID: 0, Symbol: GOOG], Time: 2882, OrderNumber: 11
2883--INFO	Last Price Set:100.00
2883--INFO	Notified Traders of trade2883---Trade ID: 7, Price: 100.00, Volume: 564 between ID:[9] and ID:[2]
2979--INFO	Enqueued order: Price: 0.00, Volume: 100, Type: SELL, Market Order: 1, Participant: 8, Stock:[ID: 0, Symbol: GOOG], Time: 2979, OrderNumber: 12
2980--INFO	Last Price Set:100.00
2980--INFO	Notified Traders of trade2980---Trade ID: 8, Price: 100.00, Volume: 100 between ID:[9] and ID:[8]
3028--INFO	Enqueued order: Price: 2147483647.00, Volume: 640, Type: BUY, Market Order: 1, Participant: 3, Stock:[ID: 0, Symbol: GOOG], Time: 3028, OrderNumber: 13
3440--INFO	Enqueued order: Price: 0.00, Volume: 233, Type: SELL, Market Order: 1, Participant: 9, Stock:[ID: 0, Symbol: GOOG], Time: 3440, OrderNumber: 14
3441--INFO	Last Price Set:100.00
3441--INFO	Notified Traders of trade3441---Trade ID: 9, Price: 100.00, Volume: 233 between ID:[8] and ID:[9]
3738--INFO	Enqueued order: Price: 0.00, Volume: 597, Type: SELL, Market Order: 1, Participant: 0, Stock:[ID: 0, Symbol: GOOG], Time: 3738, OrderNumber: 15
3739--INFO	Last Price Set:100.00
3739--INFO	Notified Traders of trade3739---Trade ID: 10, Price: 100.00, Volume: 597 between ID:[9] and ID:[0]
3771--INFO	Enqueued order: Price: 2147483647.00, Volume: 137500, Type: BUY, Market Order: 1, Participant: 11, Stock:[ID: 0, Symbol: GOOG], Time: 3771, OrderNumber: 16
3972--INFO	Enqueued order: Price: 0.00, Volume: 114, Type: SELL, Market Order: 1, Participant: 8, Stock:[ID: 0, Symbol: GOOG], Time: 3972, OrderNumber: 17
3973--INFO	Last Price Set:100.00
3973--INFO	Notified Traders of trade3973---Trade ID: 11, Price: 100.00, Volume: 114 between ID:[9] and ID:[8]
3990--INFO	Enqueued order: Price: 2147483647.00, Volume: 167500, Type: BUY, Market Order: 1, Participant: 10, Stock:[ID: 0, Symbol: GOOG], Time: 3990, OrderNumber: 18
4300--INFO	Enqueued order: Price: 0.00, Volume: 281, Type: SELL, Market Order: 1, Participant: 9, Stock:[ID: 0, Symbol: GOOG], Time: 4300, OrderNumber: 19
4301--INFO	Last Price Set:100.00
4301--INFO	Notified Traders of trade4301---Trade ID: 12, Price: 100.00, Volume: 281 between ID:[8] and ID:[9]
4542--INFO	Enqueued order: Price: 2147483647.00, Volume: 207, Type: BUY, Market Order: 1, Participant: 3, Stock:[ID: 0, Symbol: GOOG], Time: 4542, OrderNumber: 20
4740--INFO	Enqueued order: Price: 0.00, Volume: 885747, Type: SELL, Market Order: 1, Participant: 6, Stock:[ID: 0, Symbol: GOOG], Time: 4740, OrderNumber: 21
4741--INFO	Last Price Set:100.00
4741--INFO	Notified Traders of trade4741---Trade ID: 13, Price: 100.00, Volume: 137400 between ID:[9] and ID:[6]
4741--INFO	Last Price Set:100.00
4741--INFO	Notified Traders of trade4741---Trade ID: 14, Price: 100.00, Volume: 137500 between ID:[8] and ID:[6]
4741--INFO	Last Price Set:100.00
4741--INFO	Notified Traders of trade4741---Trade ID: 15, Price: 100.00, Volume: 137500 between ID:[11] and ID:[6]
4741--INFO	Last Price Set:100.00
4741--INFO	Notified Traders of trade4741---Trade ID: 16, Price: 100.00, Volume: 167500 between ID:[10] and ID:[6]
4741--INFO	Last Price Set:100.00
4741--INFO	Notified Traders of trade4741---Trade ID: 17, Price: 100.00, Volume: 640 between ID:[3] and ID:[6]
4741--INFO	Last Price Set:100.00
4741--INFO	Notified Traders of trade4741---Trade ID: 18, Price: 100.00, Volume: 137500 between ID:[11] and ID:[6]
4741--INFO	Last Price Set:100.00
4741--INFO	Notified Traders of trade4741---Trade ID: 19, Price: 100.00, Volume: 167500 between ID:[10] and ID:[6]
4741--INFO	Last Price Set:100.00
4741--INFO	Notified Traders of trade4741---Trade ID: 20, Price: 100.00, Volume: 207 between ID:[3] and ID:[6]
4965--INFO	Enqueued order: Price: 0.00, Volume: 13880, Type: SELL, Market Order: 1, Participant: 8, Stock:[ID: 0, Symbol: GOOG], Time: 4965, OrderNumber: 22
5028--INFO	Enqueued order: Price: 0.00, Volume: 27590, Type: SELL, Market Order: 1, Participant: 11, Stock:[ID: 0, Symbol: GOOG], Time: 5028, OrderNumber: 23
5160--INFO	Enqueued order: Price: 0.00, Volume: 13993, Type: SELL, Market Order: 1, Participant: 9, Stock:[ID: 0, Symbol: GOOG], Time: 5160, OrderNumber: 24
5320--INFO	Enqueued order: Price: 0.00, Volume: 33588, Type: SELL, Market Order: 1, Participant: 10, Stock:[ID: 0, Symbol: GOOG], Time: 5320, OrderNumber: 25
5358--INFO	Enqueued order: Price: 0.00, Volume: 551, Type: SELL, Market Order: 1, Participant: 1, Stock:[ID: 0, Symbol: GOOG], Time: 5358, OrderNumber: 26
5536--INFO	Enqueued order: Price: 2147483647.00, Volume: 89602, Type: BUY, Market Order: 1, Participant: 7, Stock:[ID: 0, Symbol: GOOG], Time: 5536, OrderNumber: 27
5537--INFO	Last Price Set:100.00
5537--INFO	Notified Traders of trade5537---Trade ID: 21, Price: 100.00, Volume: 13880 between ID:[7] and ID:[8]
5537--INFO	Last Price Set:100.00
5537--INFO	Notified Traders of trade5537---Trade ID: 22, Price: 100.00, Volume: 27590 between ID:[7] and ID:[11]
5537--INFO	Last Price Set:100.00
5537--INFO	Notified Traders of trade5537---Trade ID: 23, Price: 100.00, Volume: 13993 between ID:[7] and ID:[9]
5537--INFO	Last Price Set:100.00
